Workbook

Sheet CONSOLIDADO-RESUMIDO
E2: 32443436
C5: 232 | D5: Beira Rio
D6: 32556564 | F6: COM | G6: REP | H6: Total
D7: 40 | F7: 0.002 | G7: 0.015
D8: VALOR | E8: QUANT. | H8: Comissão
A9: 0.069381003 | B9: 0.07032815 | C9: 45658 | D9: 2289642.9 | E9: =D9/$D$7 -> 57241.073 | F9: =D9*$F$7 -> 4579.2858 | G9: =D9*$G$7 -> 34344.644 | H9: =F9+G9 -> 38923.929
A10: 0.10137708 | B10: 0.086162265 | C10: 45689 | D10: 2805147.3 | E10: =D10/$D$7 -> 70128.682 | F10: =D10*$F$7 -> 5610.2946 | G10: =D10*$G$7 -> 42077.209 | H10: =F10+G10 -> 47687.504
A11: 0.087520936 | B11: 0.080275023 | C11: 45717 | D11: 2613478.9 | E11: =D11/$D$7 -> 65336.973 | F11: =D11*$F$7 -> 5226.9578 | G11: =D11*$G$7 -> 39202.184 | H11: =F11+G11 -> 44429.141
A12: 0.071736784 | B12: 0.076457837 | C12: 45748 | D12: 2489204.5 | E12: =D12/$D$7 -> 62230.111 | F12: =D12*$F$7 -> 4978.4089 | G12: =D12*$G$7 -> 37338.067 | H12: =F12+G12 -> 42316.476
A13: 0.066123344 | B13: 0.069955618 | C13: 45778 | D13: 2277514.5 | E13: =D13/$D$7 -> 56937.864 | F13: =D13*$F$7 -> 4555.0291 | G13: =D13*$G$7 -> 34162.718 | H13: =F13+G13 -> 38717.747
A14: 0.079066446 | B14: 0.073453399 | C14: 45809 | D14: 2391390.3 | E14: =D14/$D$7 -> 59784.757 | F14: =D14*$F$7 -> 4782.7805 | G14: =D14*$G$7 -> 35870.854 | H14: =F14+G14 -> 40653.635
A15: 0.095001598 | B15: 0.090145231 | C15: 45839 | D15: 2934819 | E15: =D15/$D$7 -> 73370.474 | F15: =D15*$F$7 -> 5869.638 | G15: =D15*$G$7 -> 44022.285 | H15: =F15+G15 -> 49891.923
A16: 0.094879765 | B16: 0.092244826 | C16: 45870 | D16: 3003174.6 | E16: =D16/$D$7 -> 75079.365 | F16: =D16*$F$7 -> 6006.3492 | G16: =D16*$G$7 -> 45047.619 | H16: =F16+G16 -> 51053.968
A17: 0.088465197 | B17: 0.11325107 | C17: 45901 | D17: 3687065.8 | E17: =D17/$D$7 -> 92176.646 | F17: =D17*$F$7 -> 7374.1316 | G17: =D17*$G$7 -> 55305.987 | H17: =F17+G17 -> 62680.119
A18: 0.11654904 | B18: 0.11964428 | C18: 45931 | D18: 3895206.6 | E18: =D18/$D$7 -> 97380.166 | F18: =D18*$F$7 -> 7790.4133 | G18: =D18*$G$7 -> 58428.1 | H18: =F18+G18 -> 66218.513
A19: 0.088968732 | B19: 0.091331511 | C19: 45962 | D19: 2973440.2 | E19: =D19/$D$7 -> 74336.005 | F19: =D19*$F$7 -> 5946.8804 | G19: =D19*$G$7 -> 44601.603 | H19: =F19+G19 -> 50548.483
A20: 0.040930076 | B20: 0.036750787 | C20: 45992 | D20: 1196479.4 | E20: =D20/$D$7 -> 29911.984 | F20: =D20*$F$7 -> 2392.9587 | G20: =D20*$G$7 -> 17947.19 | H20: =F20+G20 -> 20340.149
B21: =SUM(B9:B20) -> 1 | J21: 0.2
D22: =SUM(D9:D21) -> 32556564 | E22: =SUM(E9:E21) -> 813914.1 | H22: =SUM(H9:H21) -> 553461.59 | J22: =D22*J21 -> 6511312.8
C23: 12 MESES | D23: =D22/12 -> 2713047 | E23: =E22/12 -> 67826.175 | H23: =H22/12 -> 46121.799
D25: VENDA GERAL-BRASIL
D26: 32443436 | E26: 0.51 | F26: COM | G26: REP | H26: Total
D27: 23 | F27: 0.01 | G27: 0.03 | H27: =H42/D42 -> 0.04
D28: VALOR | E28: QUANT. | G28: Comissão-COM | H28: Comissão
A29: 0.03878095 | B29: 0.0684 | C29: 45658 | D29: 2219131 | E29: =D29/$D$27 -> 96483.958 | F29: =D29*$F$27 -> 22191.31 | G29: =D29*$G$27 -> 66573.931 | H29: =F29+G29 -> 88765.241
A30: 0.057552667 | B30: 0.072 | C30: 45689 | D30: 2335927.4 | E30: =D30/$D$27 -> 101562.06 | F30: =D30*$F$27 -> 23359.274 | G30: =D30*$G$27 -> 70077.822 | H30: =F30+G30 -> 93437.096
A31: 0.070779466 | B31: 0.0756 | C31: 45717 | D31: 2452723.8 | E31: =D31/$D$27 -> 106640.16 | F31: =D31*$F$27 -> 24527.238 | G31: =D31*$G$27 -> 73581.713 | H31: =F31+G31 -> 98108.951
A32: 0.05150276 | B32: 0.0899 | C32: 45748 | D32: 2916664.9 | E32: =D32/$D$27 -> 126811.52 | F32: =D32*$F$27 -> 29166.649 | G32: =D32*$G$27 -> 87499.947 | H32: =F32+G32 -> 116666.6
A33: 0.055278878 | B33: 0.0947 | C33: 45778 | D33: 3072393.4 | E33: =D33/$D$27 -> 133582.32 | F33: =D33*$F$27 -> 30723.934 | G33: =D33*$G$27 -> 92171.802 | H33: =F33+G33 -> 122895.74
A34: 0.12325496 | B34: 0.0954 | C34: 45809 | D34: 3095103.8 | E34: =D34/$D$27 -> 134569.73 | F34: =D34*$F$27 -> 30951.038 | G34: =D34*$G$27 -> 92853.114 | H34: =F34+G34 -> 123804.15
A35: 0.093642628 | B35: 0.0955 | C35: 45839 | D35: 3098348.1 | E35: =D35/$D$27 -> 134710.79 | F35: =D35*$F$27 -> 30983.481 | G35: =D35*$G$27 -> 92950.444 | H35: =F35+G35 -> 123933.93
A36: 0.094573254 | B36: 0.0994 | C36: 45870 | D36: 3224877.5 | E36: =D36/$D$27 -> 140212.07 | F36: =D36*$F$27 -> 32248.775 | G36: =D36*$G$27 -> 96746.326 | H36: =F36+G36 -> 128995.1
A37: 0.10692175 | B37: 0.0933 | C37: 45901 | D37: 3026972.6 | E37: =D37/$D$27 -> 131607.5 | F37: =D37*$F$27 -> 30269.726 | G37: =D37*$G$27 -> 90809.178 | H37: =F37+G37 -> 121078.9
A38: 0.13436451 | B38: 0.0985 | C38: 45931 | D38: 3195678.5 | E38: =D38/$D$27 -> 138942.54 | F38: =D38*$F$27 -> 31956.785 | G38: =D38*$G$27 -> 95870.354 | H38: =F38+G38 -> 127827.14
A39: 0.10256833 | B39: 0.0752 | C39: 45962 | D39: 2439746.4 | E39: =D39/$D$27 -> 106075.93 | F39: =D39*$F$27 -> 24397.464 | G39: =D39*$G$27 -> 73192.392 | H39: =F39+G39 -> 97589.856
A40: 0.070779856 | B40: 0.0421 | C40: 45992 | D40: 1365868.7 | E40: =D40/$D$27 -> 59385.594 | F40: =D40*$F$27 -> 13658.687 | G40: =D40*$G$27 -> 40976.06 | H40: =F40+G40 -> 54634.746
B41: =SUM(B29:B40) -> 1 | J41: 0.15
D42: =SUM(D29:D41) -> 32443436 | E42: =SUM(E29:E41) -> 1410584.2 | G42: =SUM(G29:G41) -> 973303.08 | H42: =SUM(H29:H41) -> 1297737.4 | J42: =D42*J41 -> 4866515.4
C43: 12 MESES | D43: =D42/12 -> 2703619.7 | E43: =E42/12 -> 117548.68 | G43: =G42/12 -> 81108.59 | H43: =H42/12 -> 108144.79
D45: CONSOLIDADO
...

Sheet DISTRIBUIÇÃO
C3: VENDA GERAL-BEIRA RIO
C4: ='CONSOLIDADO-RESUMIDO'!D6 -> 32556564 | E4: 12 | J4: =E5+G5+I5 -> 1
C5: 41.45 | E5: 0.14 | G5: 0.81 | I5: 0.05
C6: VALOR | D6: QUANT. | E6: REVENDA | G6: VENDA | I6: BENEFICIAMENTO | L6: 24 | M6: =F7+H7+J7 -> 57246.827
B7: 46023 | C7: ='CONSOLIDADO-RESUMIDO'!D9 -> 2289642.9 | D7: ='CONSOLIDADO-RESUMIDO'!E9 -> 57241.073 | E7: =C7*$E$5 -> 320550.01 | F7: =E7/$C$5 -> 7733.4139 | G7: =C7*$G$5 -> 1854610.8 | H7: =G7/$C$5 -> 44743.323 | I7: =C7*$I$5 -> 114482.15 | J7: =I7/$L$6 -> 4770.0894
B8: 46054 | C8: ='CONSOLIDADO-RESUMIDO'!D10 -> 2805147.3 | D8: ='CONSOLIDADO-RESUMIDO'!E10 -> 70128.682 | E8: =C8*$E$5 -> 392720.62 | F8: =E8/$C$5 -> 9474.5627 | G8: =C8*$G$5 -> 2272169.3 | H8: =G8/$C$5 -> 54817.112 | I8: =C8*$I$5 -> 140257.36 | J8: =I8/$L$6 -> 5844.0569 | L8: 1º TRI | M8: {=SUM(F7:F9+H7:H9+J7:J9)} -> 192726.1 | N8: =SUM(C7:C9) -> 7708269.1
B9: 46082 | C9: ='CONSOLIDADO-RESUMIDO'!D11 -> 2613478.9 | D9: ='CONSOLIDADO-RESUMIDO'!E11 -> 65336.973 | E9: =C9*$E$5 -> 365887.05 | F9: =E9/$C$5 -> 8827.1905 | G9: =C9*$G$5 -> 2116917.9 | H9: =G9/$C$5 -> 51071.602 | I9: =C9*$I$5 -> 130673.95 | J9: =I9/$L$6 -> 5444.7477
B10: 46113 | C10: ='CONSOLIDADO-RESUMIDO'!D12 -> 2489204.5 | D10: ='CONSOLIDADO-RESUMIDO'!E12 -> 62230.111 | E10: =C10*$E$5 -> 348488.62 | F10: =E10/$C$5 -> 8407.4457 | G10: =C10*$G$5 -> 2016255.6 | H10: =G10/$C$5 -> 48643.079 | I10: =C10*$I$5 -> 124460.22 | J10: =I10/$L$6 -> 5185.8426
B11: 46143 | C11: ='CONSOLIDADO-RESUMIDO'!D13 -> 2277514.5 | D11: ='CONSOLIDADO-RESUMIDO'!E13 -> 56937.864 | E11: =C11*$E$5 -> 318852.04 | F11: =E11/$C$5 -> 7692.4496 | G11: =C11*$G$5 -> 1844786.8 | H11: =G11/$C$5 -> 44506.316 | I11: =C11*$I$5 -> 113875.73 | J11: =I11/$L$6 -> 4744.822 | L11: 2º TRI | M11: {=SUM(F10:F12+H10:H12+J10:J12)} -> 178970.72 | N11: =SUM(C10:C12) -> 7158109.3
B12: 46174 | C12: ='CONSOLIDADO-RESUMIDO'!D14 -> 2391390.3 | D12: ='CONSOLIDADO-RESUMIDO'!E14 -> 59784.757 | E12: =C12*$E$5 -> 334794.64 | F12: =E12/$C$5 -> 8077.0721 | G12: =C12*$G$5 -> 1937026.1 | H12: =G12/$C$5 -> 46731.631 | I12: =C12*$I$5 -> 119569.51 | J12: =I12/$L$6 -> 4982.0631
B13: 46204 | C13: ='CONSOLIDADO-RESUMIDO'!D15 -> 2934819 | D13: ='CONSOLIDADO-RESUMIDO'!E15 -> 73370.474 | E13: =C13*$E$5 -> 410874.66 | F13: =E13/$C$5 -> 9912.537 | G13: =C13*$G$5 -> 2377203.4 | H13: =G13/$C$5 -> 57351.107 | I13: =C13*$I$5 -> 146740.95 | J13: =I13/$L$6 -> 6114.2062
B14: 46235 | C14: ='CONSOLIDADO-RESUMIDO'!D16 -> 3003174.6 | D14: ='CONSOLIDADO-RESUMIDO'!E16 -> 75079.365 | E14: =C14*$E$5 -> 420444.44 | F14: =E14/$C$5 -> 10143.412 | G14: =C14*$G$5 -> 2432571.4 | H14: =G14/$C$5 -> 58686.886 | I14: =C14*$I$5 -> 150158.73 | J14: =I14/$L$6 -> 6256.6137 | L14: 3º TRI | M14: {=SUM(F13:F15+H13:H15+J13:J15)} -> 240650.67 | N14: =SUM(C13:C15) -> 9625059.4
B15: 46266 | C15: ='CONSOLIDADO-RESUMIDO'!D17 -> 3687065.8 | D15: ='CONSOLIDADO-RESUMIDO'!E17 -> 92176.646 | E15: =C15*$E$5 -> 516189.22 | F15: =E15/$C$5 -> 12453.298 | G15: =C15*$G$5 -> 2986523.3 | H15: =G15/$C$5 -> 72051.226 | I15: =C15*$I$5 -> 184353.29 | J15: =I15/$L$6 -> 7681.3871
B16: 46296 | C16: ='CONSOLIDADO-RESUMIDO'!D18 -> 3895206.6 | D16: ='CONSOLIDADO-RESUMIDO'!E18 -> 97380.166 | E16: =C16*$E$5 -> 545328.93 | F16: =E16/$C$5 -> 13156.307 | G16: =C16*$G$5 -> 3155117.4 | H16: =G16/$C$5 -> 76118.634 | I16: =C16*$I$5 -> 194760.33 | J16: =I16/$L$6 -> 8115.0138
B17: 46327 | C17: ='CONSOLIDADO-RESUMIDO'!D19 -> 2973440.2 | D17: ='CONSOLIDADO-RESUMIDO'!E19 -> 74336.005 | E17: =C17*$E$5 -> 416281.63 | F17: =E17/$C$5 -> 10042.983 | G17: =C17*$G$5 -> 2408486.5 | H17: =G17/$C$5 -> 58105.827 | I17: =C17*$I$5 -> 148672.01 | J17: =I17/$L$6 -> 6194.667 | L17: 4º TRI | M17: {=SUM(F16:F18+H16:H18+J16:J18)} -> 201648.42 | N17: =SUM(C16:C18) -> 8065126.2
B18: 46357 | C18: ='CONSOLIDADO-RESUMIDO'!D20 -> 1196479.4 | D18: ='CONSOLIDADO-RESUMIDO'!E20 -> 29911.984 | E18: =C18*$E$5 -> 167507.11 | F18: =E18/$C$5 -> 4041.1848 | G18: =C18*$G$5 -> 969148.27 | H18: =G18/$C$5 -> 23381.14 | I18: =C18*$I$5 -> 59823.968 | J18: =I18/$L$6 -> 2492.6653
C20: =SUM(C7:C19) -> 32556564 | D20: =SUM(D7:D19) -> 813914.1 | E20: =SUM(E7:E19) -> 4557919 | F20: =SUM(F7:F19) -> 109961.86 | G20: =SUM(G7:G19) -> 26370817 | H20: =SUM(H7:H19) -> 636207.88 | I20: =SUM(I7:I19) -> 1627828.2 | J20: =SUM(J7:J19) -> 67826.175 | L20: ANO | M20: =F20+H20+J20 -> 813995.92 | N20: =E20+G20+I20 -> 32556564
B21: 12 MESES | C21: =C20/12 -> 2713047 | D21: =D20/12 -> 67826.175 | J21: =M20-D20 -> 81.816858 | M21: =N20/M20 -> 39.995979
C25: VENDA GERAL-BRASIL
C26: ='CONSOLIDADO-RESUMIDO'!D26 -> 32443436 | E26: 12 | J26: =E27+G27+I27 -> 1
C27: 25 | E27: 0.8 | G27: 0.15 | I27: 0.05
C28: VALOR | D28: QUANT. | E28: REVENDA | G28: VENDA | I28: BENEFICIAMENTO | L28: 8.57
B29: 46023 | C29: ='CONSOLIDADO-RESUMIDO'!D29 -> 2219131 | D29: =C29/$C$27 -> 88765.241 | E29: =C29*$E$27 -> 1775304.8 | F29: =E29/$C$27 -> 71012.193 | G29: =C29*$G$27 -> 332869.65 | H29: =G29/$C$27 -> 13314.786 | I29: =C29*$I$27 -> 110956.55 | J29: =I29/$L$28 -> 12947.089 | L29: 1º TRI | M29: {=SUM(F29:F31+H29:H31+J29:J31)} -> 307181.27 | N29: =SUM(C29:C31) -> 7007782.2 | P29: =N29/20.94 -> 334660.09
B30: 46054 | C30: ='CONSOLIDADO-RESUMIDO'!D30 -> 2335927.4 | D30: =C30/$C$27 -> 93437.096 | E30: =C30*$E$27 -> 1868741.9 | F30: =E30/$C$27 -> 74749.677 | G30: =C30*$G$27 -> 350389.11 | H30: =G30/$C$27 -> 14015.564 | I30: =C30*$I$27 -> 116796.37 | J30: =I30/$L$28 -> 13628.515
B31: 46082 | C31: ='CONSOLIDADO-RESUMIDO'!D31 -> 2452723.8 | D31: =C31/$C$27 -> 98108.951 | E31: =C31*$E$27 -> 1962179 | F31: =E31/$C$27 -> 78487.161 | G31: =C31*$G$27 -> 367908.56 | H31: =G31/$C$27 -> 14716.343 | I31: =C31*$I$27 -> 122636.19 | J31: =I31/$L$28 -> 14309.94
B32: 46113 | C32: ='CONSOLIDADO-RESUMIDO'!D32 -> 2916664.9 | D32: =C32/$C$27 -> 116666.6 | E32: =C32*$E$27 -> 2333331.9 | F32: =E32/$C$27 -> 93333.277 | G32: =C32*$G$27 -> 437499.74 | H32: =G32/$C$27 -> 17499.989 | I32: =C32*$I$27 -> 145833.25 | J32: =I32/$L$28 -> 17016.715 | L32: 2º TRI | M32: {=SUM(F32:F34+H32:H34+J32:J34)} -> 398197.94 | N32: =SUM(C32:C34) -> 9084162.1
B33: 46143 | C33: ='CONSOLIDADO-RESUMIDO'!D33 -> 3072393.4 | D33: =C33/$C$27 -> 122895.74 | E33: =C33*$E$27 -> 2457914.7 | F33: =E33/$C$27 -> 98316.589 | G33: =C33*$G$27 -> 460859.01 | H33: =G33/$C$27 -> 18434.36 | I33: =C33*$I$27 -> 153619.67 | J33: =I33/$L$28 -> 17925.282
B34: 46174 | C34: ='CONSOLIDADO-RESUMIDO'!D34 -> 3095103.8 | D34: =C34/$C$27 -> 123804.15 | E34: =C34*$E$27 -> 2476083 | F34: =E34/$C$27 -> 99043.322 | G34: =C34*$G$27 -> 464265.57 | H34: =G34/$C$27 -> 18570.623 | I34: =C34*$I$27 -> 154755.19 | J34: =I34/$L$28 -> 18057.782
B35: 46204 | C35: ='CONSOLIDADO-RESUMIDO'!D35 -> 3098348.1 | D35: =C35/$C$27 -> 123933.93 | E35: =C35*$E$27 -> 2478678.5 | F35: =E35/$C$27 -> 99147.141 | G35: =C35*$G$27 -> 464752.22 | H35: =G35/$C$27 -> 18590.089 | I35: =C35*$I$27 -> 154917.41 | J35: =I35/$L$28 -> 18076.71 | L35: 3º TRI | M35: {=SUM(F35:F37+H35:H37+J35:J37)} -> 409859.45 | N35: =SUM(C35:C37) -> 9350198.3
B36: 46235 | C36: ='CONSOLIDADO-RESUMIDO'!D36 -> 3224877.5 | D36: =C36/$C$27 -> 128995.1 | E36: =C36*$E$27 -> 2579902 | F36: =E36/$C$27 -> 103196.08 | G36: =C36*$G$27 -> 483731.63 | H36: =G36/$C$27 -> 19349.265 | I36: =C36*$I$27 -> 161243.88 | J36: =I36/$L$28 -> 18814.921
B37: 46266 | C37: ='CONSOLIDADO-RESUMIDO'!D37 -> 3026972.6 | D37: =C37/$C$27 -> 121078.9 | E37: =C37*$E$27 -> 2421578.1 | F37: =E37/$C$27 -> 96863.123 | G37: =C37*$G$27 -> 454045.89 | H37: =G37/$C$27 -> 18161.836 | I37: =C37*$I$27 -> 151348.63 | J37: =I37/$L$28 -> 17660.283
B38: 46296 | C38: ='CONSOLIDADO-RESUMIDO'!D38 -> 3195678.5 | D38: =C38/$C$27 -> 127827.14 | E38: =C38*$E$27 -> 2556542.8 | F38: =E38/$C$27 -> 102261.71 | G38: =C38*$G$27 -> 479351.77 | H38: =G38/$C$27 -> 19174.071 | I38: =C38*$I$27 -> 159783.92 | J38: =I38/$L$28 -> 18644.565 | L38: 4º TRI | M38: {=SUM(F38:F40+H38:H40+J38:J40)} -> 306896.84 | N38: =SUM(C38:C40) -> 7001293.5
B39: 46327 | C39: ='CONSOLIDADO-RESUMIDO'!D39 -> 2439746.4 | D39: =C39/$C$27 -> 97589.856 | E39: =C39*$E$27 -> 1951797.1 | F39: =E39/$C$27 -> 78071.885 | G39: =C39*$G$27 -> 365961.96 | H39: =G39/$C$27 -> 14638.478 | I39: =C39*$I$27 -> 121987.32 | J39: =I39/$L$28 -> 14234.226
B40: 46357 | C40: ='CONSOLIDADO-RESUMIDO'!D40 -> 1365868.7 | D40: =C40/$C$27 -> 54634.746 | E40: =C40*$E$27 -> 1092694.9 | F40: =E40/$C$27 -> 43707.797 | G40: =C40*$G$27 -> 204880.3 | H40: =G40/$C$27 -> 8195.2119 | I40: =C40*$I$27 -> 68293.433 | J40: =I40/$L$28 -> 7968.8953
L41: ANO | M41: =M29+M32+M35+M38 -> 1422135.5 | N41: =N38+N35+N32+N29 -> 32443436
C42: =SUM(C29:C41) -> 32443436 | D42: =SUM(D29:D41) -> 1297737.4 | E42: =SUM(E29:E41) -> 25954749 | F42: =SUM(F29:F41) -> 1038190 | G42: =SUM(G29:G41) -> 4866515.4 | H42: =SUM(H29:H41) -> 194660.62 | I42: =SUM(I29:I41) -> 1622171.8 | J42: =SUM(J29:J41) -> 189284.92 | M42: =N41/M41 -> 22.813182
B43: 12 MESES | C43: =C42/12 -> 2703619.7 | D43: =D42/12 -> 108144.79 | J43: =M42-D42 -> -1297714.6
C46: VENDA GERAL CONSOLIDADA
C47: =C63 -> 65000000 | J47: =E48+G48+I48 -> 1
C48: =C63/D63 -> 30.781594 | E48: =E63/C63 -> 0.46942566 | G48: =G63/C63 -> 0.48057434 | I48: =I63/C63 -> 0.05
...

Sheet PROD.INDUSTRIA
C1: PRODUÇÃO GERAL-BEIRA RIO
C2: =C18 -> 813914.1
M3: REVENDA
C4: QUANTIDADE | D4: DIAS UTEIS | E4: PRODUÇÃO | F4: MEDIA DIA | G4: BENEFICIAMENTO | H4: MEDIA DIA | I4: TOTAL | J4: MEDIA DIA | M4: 0.2
B5: 46023 | C5: {=DISTRIBUIÇÃO!D7:D18} -> 57241.073 | D5: 18 | E5: =DISTRIBUIÇÃO!F7+DISTRIBUIÇÃO!H7-PROD.INDUSTRIA!M5 -> 50930.054 | F5: =E5/D5 -> 2829.4475 | G5: =DISTRIBUIÇÃO!J7 -> 4770.0894 | H5: =G5/D5 -> 265.00497 | I5: =E5+G5 -> 55700.144 | J5: =I5/D5 -> 3094.4524 | M5: =DISTRIBUIÇÃO!F7*PROD.INDUSTRIA!$M$4 -> 1546.6828
B6: 46054 | C6: 70128.682 | D6: 20 | E6: =DISTRIBUIÇÃO!F8+DISTRIBUIÇÃO!H8-PROD.INDUSTRIA!M6 -> 62396.763 | F6: =E6/D6 -> 3119.8381 | G6: =DISTRIBUIÇÃO!J8 -> 5844.0569 | H6: =G6/D6 -> 292.20284 | I6: =E6+G6 -> 68240.819 | J6: =I6/D6 -> 3412.041 | M6: =DISTRIBUIÇÃO!F8*PROD.INDUSTRIA!$M$4 -> 1894.9125
B7: 46082 | C7: 65336.973 | D7: 22 | E7: =DISTRIBUIÇÃO!F9+DISTRIBUIÇÃO!H9-PROD.INDUSTRIA!M7 -> 58133.355 | F7: =E7/D7 -> 2642.4252 | G7: =DISTRIBUIÇÃO!J9 -> 5444.7477 | H7: =G7/D7 -> 247.48853 | I7: =E7+G7 -> 63578.102 | J7: =I7/D7 -> 2889.9137 | M7: =DISTRIBUIÇÃO!F9*PROD.INDUSTRIA!$M$4 -> 1765.4381
B8: 46113 | C8: 62230.111 | D8: 21 | E8: =DISTRIBUIÇÃO!F10+DISTRIBUIÇÃO!H10-PROD.INDUSTRIA!M8 -> 55369.035 | F8: =E8/D8 -> 2636.6207 | G8: =DISTRIBUIÇÃO!J10 -> 5185.8426 | H8: =G8/D8 -> 246.94489 | I8: =E8+G8 -> 60554.878 | J8: =I8/D8 -> 2883.5656 | M8: =DISTRIBUIÇÃO!F10*PROD.INDUSTRIA!$M$4 -> 1681.4891
B9: 46143 | C9: 56937.864 | D9: 19 | E9: =DISTRIBUIÇÃO!F11+DISTRIBUIÇÃO!H11-PROD.INDUSTRIA!M9 -> 50660.275 | F9: =E9/D9 -> 2666.3303 | G9: =DISTRIBUIÇÃO!J11 -> 4744.822 | H9: =G9/D9 -> 249.72747 | I9: =E9+G9 -> 55405.097 | J9: =I9/D9 -> 2916.0578 | M9: =DISTRIBUIÇÃO!F11*PROD.INDUSTRIA!$M$4 -> 1538.4899
B10: 46174 | C10: 59784.757 | D10: 22 | E10: =DISTRIBUIÇÃO!F12+DISTRIBUIÇÃO!H12-PROD.INDUSTRIA!M10 -> 53193.289 | F10: =E10/D10 -> 2417.8768 | G10: =DISTRIBUIÇÃO!J12 -> 4982.0631 | H10: =G10/D10 -> 226.45741 | I10: =E10+G10 -> 58175.352 | J10: =I10/D10 -> 2644.3342 | M10: =DISTRIBUIÇÃO!F12*PROD.INDUSTRIA!$M$4 -> 1615.4144
B11: 46204 | C11: 73370.474 | D11: 22 | E11: =DISTRIBUIÇÃO!F13+DISTRIBUIÇÃO!H13-PROD.INDUSTRIA!M11 -> 65281.136 | F11: =E11/D11 -> 2967.3244 | G11: =DISTRIBUIÇÃO!J13 -> 6114.2062 | H11: =G11/D11 -> 277.91846 | I11: =E11+G11 -> 71395.342 | J11: =I11/D11 -> 3245.2428 | M11: =DISTRIBUIÇÃO!F13*PROD.INDUSTRIA!$M$4 -> 1982.5074
B12: 46235 | C12: 75079.365 | D12: 22 | E12: =DISTRIBUIÇÃO!F14+DISTRIBUIÇÃO!H14-PROD.INDUSTRIA!M12 -> 66801.616 | F12: =E12/D12 -> 3036.4371 | G12: =DISTRIBUIÇÃO!J14 -> 6256.6137 | H12: =G12/D12 -> 284.39153 | I12: =E12+G12 -> 73058.229 | J12: =I12/D12 -> 3320.8286 | M12: =DISTRIBUIÇÃO!F14*PROD.INDUSTRIA!$M$4 -> 2028.6825
B13: 46266 | C13: 92176.646 | D13: 20 | E13: =DISTRIBUIÇÃO!F15+DISTRIBUIÇÃO!H15-PROD.INDUSTRIA!M13 -> 82013.865 | F13: =E13/D13 -> 4100.6932 | G13: =DISTRIBUIÇÃO!J15 -> 7681.3871 | H13: =G13/D13 -> 384.06936 | I13: =E13+G13 -> 89695.252 | J13: =I13/D13 -> 4484.7626 | M13: =DISTRIBUIÇÃO!F15*PROD.INDUSTRIA!$M$4 -> 2490.6597
B14: 46296 | C14: 97380.166 | D14: 20 | E14: =DISTRIBUIÇÃO!F16+DISTRIBUIÇÃO!H16-PROD.INDUSTRIA!M14 -> 86643.68 | F14: =E14/D14 -> 4332.184 | G14: =DISTRIBUIÇÃO!J16 -> 8115.0138 | H14: =G14/D14 -> 405.75069 | I14: =E14+G14 -> 94758.693 | J14: =I14/D14 -> 4737.9347 | M14: =DISTRIBUIÇÃO!F16*PROD.INDUSTRIA!$M$4 -> 2631.2614
B15: 46327 | C15: 74336.005 | D15: 20 | E15: =DISTRIBUIÇÃO!F17+DISTRIBUIÇÃO!H17-PROD.INDUSTRIA!M15 -> 66140.213 | F15: =E15/D15 -> 3307.0107 | G15: =DISTRIBUIÇÃO!J17 -> 6194.667 | H15: =G15/D15 -> 309.73335 | I15: =E15+G15 -> 72334.88 | J15: =I15/D15 -> 3616.744 | M15: =DISTRIBUIÇÃO!F17*PROD.INDUSTRIA!$M$4 -> 2008.5965
B16: 46357 | C16: 29911.984 | D16: 12 | E16: =DISTRIBUIÇÃO!F18+DISTRIBUIÇÃO!H18-PROD.INDUSTRIA!M16 -> 26614.088 | F16: =E16/D16 -> 2217.8407 | G16: =DISTRIBUIÇÃO!J18 -> 2492.6653 | H16: =G16/D16 -> 207.72211 | I16: =E16+G16 -> 29106.754 | J16: =I16/D16 -> 2425.5628 | M16: =DISTRIBUIÇÃO!F18*PROD.INDUSTRIA!$M$4 -> 808.23696
C18: =SUM(C5:C17) -> 813914.1 | D18: =SUM(D5:D17) -> 238 | E18: =SUM(E5:E16) -> 724177.37 | G18: =SUM(G5:G16) -> 67826.175 | I18: =SUM(I5:I16) -> 792003.54
B19: 12 MESES | C19: =C18/12 -> 67826.175 | D19: =D18/12 -> 19.833333
C21: PRODUÇÃO GERAL-BRASIL
C22: =C38 -> 1297737.4
C24: QUANTIDADE | D24: DIAS UTEIS | E24: PRODUÇÃO | F24: MEDIA DIA | G24: BENEFICIAMENTO | H24: MEDIA DIA | I24: TOTAL | J24: MEDIA DIA | M24: 0.2
B25: 46023 | C25: =DISTRIBUIÇÃO!D29 -> 88765.241 | D25: {=D5:D16} -> 18 | E25: =DISTRIBUIÇÃO!F29+DISTRIBUIÇÃO!H29-PROD.INDUSTRIA!M25 -> 70124.54 | F25: =E25/D25 -> 3895.8078 | G25: =DISTRIBUIÇÃO!J29 -> 12947.089 | H25: =G25/D25 -> 719.28271 | I25: =E25+G25 -> 83071.629 | J25: =I25/D25 -> 4615.0905 | M25: =DISTRIBUIÇÃO!F29*PROD.INDUSTRIA!$M$24 -> 14202.439
B26: 46054 | C26: =DISTRIBUIÇÃO!D30 -> 93437.096 | D26: 20 | E26: =DISTRIBUIÇÃO!F30+DISTRIBUIÇÃO!H30-PROD.INDUSTRIA!M26 -> 73815.306 | F26: =E26/D26 -> 3690.7653 | G26: =DISTRIBUIÇÃO!J30 -> 13628.515 | H26: =G26/D26 -> 681.42573 | I26: =E26+G26 -> 87443.82 | J26: =I26/D26 -> 4372.191 | M26: =DISTRIBUIÇÃO!F30*PROD.INDUSTRIA!$M$24 -> 14949.935
B27: 46082 | C27: =DISTRIBUIÇÃO!D31 -> 98108.951 | D27: 22 | E27: =DISTRIBUIÇÃO!F31+DISTRIBUIÇÃO!H31-PROD.INDUSTRIA!M27 -> 77506.071 | F27: =E27/D27 -> 3523.0032 | G27: =DISTRIBUIÇÃO!J31 -> 14309.94 | H27: =G27/D27 -> 650.45183 | I27: =E27+G27 -> 91816.011 | J27: =I27/D27 -> 4173.4551 | M27: =DISTRIBUIÇÃO!F31*PROD.INDUSTRIA!$M$24 -> 15697.432
B28: 46113 | C28: =DISTRIBUIÇÃO!D32 -> 116666.6 | D28: 21 | E28: =DISTRIBUIÇÃO!F32+DISTRIBUIÇÃO!H32-PROD.INDUSTRIA!M28 -> 92166.611 | F28: =E28/D28 -> 4388.8862 | G28: =DISTRIBUIÇÃO!J32 -> 17016.715 | H28: =G28/D28 -> 810.31975 | I28: =E28+G28 -> 109183.33 | J28: =I28/D28 -> 5199.206 | M28: =DISTRIBUIÇÃO!F32*PROD.INDUSTRIA!$M$24 -> 18666.655
B29: 46143 | C29: =DISTRIBUIÇÃO!D33 -> 122895.74 | D29: 19 | E29: =DISTRIBUIÇÃO!F33+DISTRIBUIÇÃO!H33-PROD.INDUSTRIA!M29 -> 97087.631 | F29: =E29/D29 -> 5109.8753 | G29: =DISTRIBUIÇÃO!J33 -> 17925.282 | H29: =G29/D29 -> 943.43591 | I29: =E29+G29 -> 115012.91 | J29: =I29/D29 -> 6053.3112 | M29: =DISTRIBUIÇÃO!F33*PROD.INDUSTRIA!$M$24 -> 19663.318
B30: 46174 | C30: =DISTRIBUIÇÃO!D34 -> 123804.15 | D30: 22 | E30: =DISTRIBUIÇÃO!F34+DISTRIBUIÇÃO!H34-PROD.INDUSTRIA!M30 -> 97805.28 | F30: =E30/D30 -> 4445.6945 | G30: =DISTRIBUIÇÃO!J34 -> 18057.782 | H30: =G30/D30 -> 820.80826 | I30: =E30+G30 -> 115863.06 | J30: =I30/D30 -> 5266.5028 | M30: =DISTRIBUIÇÃO!F34*PROD.INDUSTRIA!$M$24 -> 19808.664
B31: 46204 | C31: =DISTRIBUIÇÃO!D35 -> 123933.93 | D31: 22 | E31: =DISTRIBUIÇÃO!F35+DISTRIBUIÇÃO!H35-PROD.INDUSTRIA!M31 -> 97907.801 | F31: =E31/D31 -> 4450.3546 | G31: =DISTRIBUIÇÃO!J35 -> 18076.71 | H31: =G31/D31 -> 821.66865 | I31: =E31+G31 -> 115984.51 | J31: =I31/D31 -> 5272.0233 | M31: =DISTRIBUIÇÃO!F35*PROD.INDUSTRIA!$M$24 -> 19829.428
B32: 46235 | C32: =DISTRIBUIÇÃO!D36 -> 128995.1 | D32: 22 | E32: =DISTRIBUIÇÃO!F36+DISTRIBUIÇÃO!H36-PROD.INDUSTRIA!M32 -> 101906.13 | F32: =E32/D32 -> 4632.0968 | G32: =DISTRIBUIÇÃO!J36 -> 18814.921 | H32: =G32/D32 -> 855.2237 | I32: =E32+G32 -> 120721.05 | J32: =I32/D32 -> 5487.3205 | M32: =DISTRIBUIÇÃO!F36*PROD.INDUSTRIA!$M$24 -> 20639.216
B33: 46266 | C33: =DISTRIBUIÇÃO!D37 -> 121078.9 | D33: 20 | E33: =DISTRIBUIÇÃO!F37+DISTRIBUIÇÃO!H37-PROD.INDUSTRIA!M33 -> 95652.334 | F33: =E33/D33 -> 4782.6167 | G33: =DISTRIBUIÇÃO!J37 -> 17660.283 | H33: =G33/D33 -> 883.01417 | I33: =E33+G33 -> 113312.62 | J33: =I33/D33 -> 5665.6309 | M33: =DISTRIBUIÇÃO!F37*PROD.INDUSTRIA!$M$24 -> 19372.625
B34: 46296 | C34: =DISTRIBUIÇÃO!D38 -> 127827.14 | D34: 20 | E34: =DISTRIBUIÇÃO!F38+DISTRIBUIÇÃO!H38-PROD.INDUSTRIA!M34 -> 100983.44 | F34: =E34/D34 -> 5049.172 | G34: =DISTRIBUIÇÃO!J38 -> 18644.565 | H34: =G34/D34 -> 932.22825 | I34: =E34+G34 -> 119628 | J34: =I34/D34 -> 5981.4002 | M34: =DISTRIBUIÇÃO!F38*PROD.INDUSTRIA!$M$24 -> 20452.342
B35: 46327 | C35: =DISTRIBUIÇÃO!D39 -> 97589.856 | D35: 20 | E35: =DISTRIBUIÇÃO!F39+DISTRIBUIÇÃO!H39-PROD.INDUSTRIA!M35 -> 77095.986 | F35: =E35/D35 -> 3854.7993 | G35: =DISTRIBUIÇÃO!J39 -> 14234.226 | H35: =G35/D35 -> 711.71132 | I35: =E35+G35 -> 91330.212 | J35: =I35/D35 -> 4566.5106 | M35: =DISTRIBUIÇÃO!F39*PROD.INDUSTRIA!$M$24 -> 15614.377
B36: 46357 | C36: =DISTRIBUIÇÃO!D40 -> 54634.746 | D36: 12 | E36: =DISTRIBUIÇÃO!F40+DISTRIBUIÇÃO!H40-PROD.INDUSTRIA!M36 -> 43161.45 | F36: =E36/D36 -> 3596.7875 | G36: =DISTRIBUIÇÃO!J40 -> 7968.8953 | H36: =G36/D36 -> 664.07461 | I36: =E36+G36 -> 51130.345 | J36: =I36/D36 -> 4260.8621 | M36: =DISTRIBUIÇÃO!F40*PROD.INDUSTRIA!$M$24 -> 8741.5594
C38: =SUM(C25:C37) -> 1297737.4 | D38: =SUM(D25:D37) -> 238 | E38: =SUM(E25:E36) -> 1025212.6 | G38: =SUM(G25:G36) -> 189284.92 | I38: =SUM(I25:I36) -> 1214497.5
B39: 12 MESES | C39: =C38/12 -> 108144.79 | D39: =D38/12 -> 19.833333 | H39: REVENDA
C41: PRODUÇÃO GERAL
C42: =C22+C2 -> 2111651.5
K43: DIA | L43: MÊS
C44: QUANTIDADE | D44: DIAS UTEIS | E44: PRODUÇÃO | F44: MEDIA DIA | G44: BENEFICIAMENTO | H44: MEDIA DIA | I44: TOTAL | J44: MEDIA DIA | K44: 9000 | L44: =K44*20 -> 180000
B45: 46023 | C45: =C25+C5 -> 146006.31 | D45: {=D5:D16} -> 18 | E45: =E5+E25 -> 121054.59 | F45: =E45/D45 -> 6725.2553 | G45: =G5+G25 -> 17717.178 | H45: =G45/D45 -> 984.28768 | I45: =E45+G45 -> 138771.77 | J45: =I45/D45 -> 7709.543 | K45: =$K$44-J45 -> 1290.457 | L45: =K45*D45 -> 23228.227
...

Sheet COMPRAS-QUANT
C2: =#REF! -> #REF! | E2: 12 | J2: =E3+G3+I3 -> 0
C3: =#REF! -> #REF!
C4: VALOR | D4: QUANT. | E4: BASES | G4: PRODUTO ACABADO | I4: TOTAL
B5: 46388 | F5: =DISTRIBUIÇÃO!F7+DISTRIBUIÇÃO!H7+DISTRIBUIÇÃO!F29+DISTRIBUIÇÃO!H29-PROD.INDUSTRIA!M5-PROD.INDUSTRIA!M25 -> 121054.59 | H5: =PROD.INDUSTRIA!M5+PROD.INDUSTRIA!M25 -> 15749.121 | J5: =F5+H5 -> 136803.72 | L5: =J5+H5+F5 -> 273607.43
B6: 46419 | F6: =DISTRIBUIÇÃO!F8+DISTRIBUIÇÃO!H8+DISTRIBUIÇÃO!F30+DISTRIBUIÇÃO!H30-PROD.INDUSTRIA!M6-PROD.INDUSTRIA!M26 -> 136212.07 | H6: =PROD.INDUSTRIA!M6+PROD.INDUSTRIA!M26 -> 16844.848 | J6: =F6+H6 -> 153056.92
B7: 46447 | F7: =DISTRIBUIÇÃO!F9+DISTRIBUIÇÃO!H9+DISTRIBUIÇÃO!F31+DISTRIBUIÇÃO!H31-PROD.INDUSTRIA!M7-PROD.INDUSTRIA!M27 -> 135639.43 | H7: =PROD.INDUSTRIA!M7+PROD.INDUSTRIA!M27 -> 17462.87 | J7: =F7+H7 -> 153102.3
B8: 46478 | F8: =DISTRIBUIÇÃO!F10+DISTRIBUIÇÃO!H10+DISTRIBUIÇÃO!F32+DISTRIBUIÇÃO!H32-PROD.INDUSTRIA!M8-PROD.INDUSTRIA!M28 -> 147535.65 | H8: =PROD.INDUSTRIA!M8+PROD.INDUSTRIA!M28 -> 20348.145 | J8: =F8+H8 -> 167883.79
B9: 46508 | F9: =DISTRIBUIÇÃO!F11+DISTRIBUIÇÃO!H11+DISTRIBUIÇÃO!F33+DISTRIBUIÇÃO!H33-PROD.INDUSTRIA!M9-PROD.INDUSTRIA!M29 -> 147747.91 | H9: =PROD.INDUSTRIA!M9+PROD.INDUSTRIA!M29 -> 21201.808 | J9: =F9+H9 -> 168949.71
B10: 46539 | F10: =DISTRIBUIÇÃO!F12+DISTRIBUIÇÃO!H12+DISTRIBUIÇÃO!F34+DISTRIBUIÇÃO!H34-PROD.INDUSTRIA!M10-PROD.INDUSTRIA!M30 -> 150998.57 | H10: =PROD.INDUSTRIA!M10+PROD.INDUSTRIA!M30 -> 21424.079 | J10: =F10+H10 -> 172422.65
B11: 46569 | F11: =DISTRIBUIÇÃO!F13+DISTRIBUIÇÃO!H13+DISTRIBUIÇÃO!F35+DISTRIBUIÇÃO!H35-PROD.INDUSTRIA!M11-PROD.INDUSTRIA!M31 -> 163188.94 | H11: =PROD.INDUSTRIA!M11+PROD.INDUSTRIA!M31 -> 21811.936 | J11: =F11+H11 -> 185000.87
B12: 46600 | F12: =DISTRIBUIÇÃO!F14+DISTRIBUIÇÃO!H14+DISTRIBUIÇÃO!F36+DISTRIBUIÇÃO!H36-PROD.INDUSTRIA!M12-PROD.INDUSTRIA!M32 -> 168707.75 | H12: =PROD.INDUSTRIA!M12+PROD.INDUSTRIA!M32 -> 22667.899 | J12: =F12+H12 -> 191375.64
B13: 46631 | F13: =DISTRIBUIÇÃO!F15+DISTRIBUIÇÃO!H15+DISTRIBUIÇÃO!F37+DISTRIBUIÇÃO!H37-PROD.INDUSTRIA!M13-PROD.INDUSTRIA!M33 -> 177666.2 | H13: =PROD.INDUSTRIA!M13+PROD.INDUSTRIA!M33 -> 21863.284 | J13: =F13+H13 -> 199529.48
B14: 46661 | F14: =DISTRIBUIÇÃO!F16+DISTRIBUIÇÃO!H16+DISTRIBUIÇÃO!F38+DISTRIBUIÇÃO!H38-PROD.INDUSTRIA!M14-PROD.INDUSTRIA!M34 -> 187627.12 | H14: =PROD.INDUSTRIA!M14+PROD.INDUSTRIA!M34 -> 23083.604 | J14: =F14+H14 -> 210710.72
B15: 46692 | F15: =DISTRIBUIÇÃO!F17+DISTRIBUIÇÃO!H17+DISTRIBUIÇÃO!F39+DISTRIBUIÇÃO!H39-PROD.INDUSTRIA!M15-PROD.INDUSTRIA!M35 -> 143236.2 | H15: =PROD.INDUSTRIA!M15+PROD.INDUSTRIA!M35 -> 17622.973 | J15: =F15+H15 -> 160859.17
B16: 46722 | F16: =DISTRIBUIÇÃO!F18+DISTRIBUIÇÃO!H18+DISTRIBUIÇÃO!F40+DISTRIBUIÇÃO!H40-PROD.INDUSTRIA!M16-PROD.INDUSTRIA!M36 -> 69775.538 | H16: =PROD.INDUSTRIA!M16+PROD.INDUSTRIA!M36 -> 9549.7964 | J16: =F16+H16 -> 79325.334
C18: =SUM(C5:C17) -> 0 | D18: =SUM(D5:D17) -> 0 | E18: =SUM(E5:E16) -> 0 | F18: =SUM(F5:F16) -> 1749389.9 | G18: =SUM(G5:G16) -> 0 | H18: =SUM(H5:H16) -> 229630.36 | I18: =SUM(I5:I16) -> 0 | J18: =SUM(J5:J16) -> 1979020.3 | L18: =F18+H18+J18 -> 3958040.6 | M18: =E18+G18+I18 -> 0
B19: 12 MESES | C19: =C18/12 -> 0 | D19: =D18/12 -> 0 | J19: =L18-D18 -> 3958040.6
C21: Ciclo abastecimento
D22: CICLO 90 DIAS(30 PARA PRODUZIR E 60 VIAGEM E DESEMBARAÇO)
D23: ESTOQUE | E23: CHEGANDO | F23: EM TRANSITO | G23: EM PRODUÇÃO | J23: MÊS | L23: CHEGANDO | M23: EM TRANSITO | N23: EM PRODUÇÃO
C24: FAT.METRAGEM | D24: 3 | E24: 1 | F24: 1 | G24: 1 | J24: EXECUÇÃO | L24: 1 | M24: 1 | N24: 1
B25: 46388 | C25: =F5+H5 -> 136803.72 | D25: =C25*$D$24 -> 410411.15 | E25: =C26 -> 153056.92 | F25: =C27 -> 153102.3 | G25: =C28 -> 167883.79 | J25: JANEIRO | L25: =J26 -> FEVEREIRO | M25: =J27 -> MARÇO | N25: =J28 -> ABRIL
B26: 46419 | C26: =F6+H6 -> 153056.92 | D26: =C26*$D$24 -> 459170.75 | E26: =C27 -> 153102.3 | F26: =C28 -> 167883.79 | G26: =C29 -> 168949.71 | J26: FEVEREIRO | L26: =J27 -> MARÇO | M26: =J28 -> ABRIL | N26: =J29 -> MAIO
B27: 46447 | C27: =F7+H7 -> 153102.3 | D27: =C27*$D$24 -> 459306.89 | E27: =C28 -> 167883.79 | F27: =C29 -> 168949.71 | G27: =C30 -> 172422.65 | J27: MARÇO | L27: =J28 -> ABRIL | M27: =J29 -> MAIO | N27: =J30 -> JUNHO
B28: 46478 | C28: =F8+H8 -> 167883.79 | D28: =C28*$D$24 -> 503651.37 | E28: =C29 -> 168949.71 | F28: =C30 -> 172422.65 | G28: =C31 -> 185000.87 | J28: ABRIL | L28: =J29 -> MAIO | M28: =J30 -> JUNHO | N28: =J31 -> JULHO
B29: 46508 | C29: =F9+H9 -> 168949.71 | D29: =C29*$D$24 -> 506849.14 | E29: =C30 -> 172422.65 | F29: =C31 -> 185000.87 | G29: =C32 -> 191375.64 | J29: MAIO | L29: =J30 -> JUNHO | M29: =J31 -> JULHO | N29: =J32 -> AGOSTO
B30: 46539 | C30: =F10+H10 -> 172422.65 | D30: =C30*$D$24 -> 517267.94 | E30: =C31 -> 185000.87 | F30: =C32 -> 191375.64 | G30: =C33 -> 199529.48 | J30: JUNHO | L30: =J31 -> JULHO | M30: =J32 -> AGOSTO | N30: =J33 -> SETEMBRO
B31: 46569 | C31: =F11+H11 -> 185000.87 | D31: =C31*$D$24 -> 555002.62 | E31: =C32 -> 191375.64 | F31: =C33 -> 199529.48 | G31: =C34 -> 210710.72 | J31: JULHO | L31: =J32 -> AGOSTO | M31: =J33 -> SETEMBRO | N31: =J34 -> OUTUBRO
B32: 46600 | C32: =F12+H12 -> 191375.64 | D32: =C32*$D$24 -> 574126.93 | E32: =C33 -> 199529.48 | F32: =C34 -> 210710.72 | G32: =C35 -> 160859.17 | J32: AGOSTO | L32: =J33 -> SETEMBRO | M32: =J34 -> OUTUBRO | N32: =J35 -> NOVEMBRO
B33: 46631 | C33: =F13+H13 -> 199529.48 | D33: =C33*$D$24 -> 598588.45 | E33: =C34 -> 210710.72 | F33: =C35 -> 160859.17 | G33: =C36 -> 79325.334 | J33: SETEMBRO | L33: =J34 -> OUTUBRO | M33: =J35 -> NOVEMBRO | N33: =J36 -> DEZEMBRO
B34: 46661 | C34: =F14+H14 -> 210710.72 | D34: =C34*$D$24 -> 632132.17 | E34: =C35 -> 160859.17 | F34: =C36 -> 79325.334 | G34: =C25 -> 136803.72 | J34: OUTUBRO | L34: =J35 -> NOVEMBRO | M34: =J36 -> DEZEMBRO | N34: =J25 -> JANEIRO
B35: 46692 | C35: =F15+H15 -> 160859.17 | D35: =C35*$D$24 -> 482577.52 | E35: =C36 -> 79325.334 | F35: =C25 -> 136803.72 | G35: =C26 -> 153056.92 | J35: NOVEMBRO | L35: =J36 -> DEZEMBRO | M35: =J25 -> JANEIRO | N35: =J26 -> FEVEREIRO
B36: 46722 | C36: =F16+H16 -> 79325.334 | D36: =C36*$D$24 -> 237976 | E36: =C25 -> 136803.72 | F36: =C26 -> 153056.92 | G36: =C27 -> 153102.3 | J36: DEZEMBRO | L36: =J25 -> JANEIRO | M36: =J26 -> FEVEREIRO | N36: =J27 -> MARÇO
C37: =SUM(C25:C36) -> 1979020.3

Sheet COMPRAS-$
D2: COMPRAS-GERAL- BASES E PRODUTO ACABADO
D3: =D19 -> 5541256.9
C4: Base $ | D4: 2.8
D5: VALOR | E5: QUANT. | F5: CHEGANDO | G5: EM TRANSITO | H5: EM PRODUÇÃO
C6: 46388 | D6: =E6*$D$4 -> 383050.41 | E6: {=DISTRIBUIÇÃO!C70:C81} -> 136803.72 | F6: =F26 -> 428559.37 | G6: =G26 -> 428686.43 | H6: =H26 -> 470074.61 | J6: 46113 | L6: =F6+G6+H6 -> 1327320.4
C7: 46419 | D7: =E7*$D$4 -> 428559.37 | E7: 153056.92 | F7: =F28 -> 428686.43 | G7: =G28 -> 470074.61 | H7: =H28 -> 473059.2 | J7: 46143 | L7: =F7+G7+H7 -> 1371820.2
C8: 46447 | D8: =E8*$D$4 -> 428686.43 | E8: 153102.3 | F8: =F30 -> 470074.61 | G8: =G30 -> 473059.2 | H8: =H30 -> 482783.41 | J8: 46174 | L8: =F8+G8+H8 -> 1425917.2
C9: 46478 | D9: =E9*$D$4 -> 470074.61 | E9: 167883.79 | F9: =F32 -> 473059.2 | G9: =G32 -> 482783.41 | H9: =H32 -> 518002.44 | J9: 46204 | L9: =F9+G9+H9 -> 1473845.1
C10: 46508 | D10: =E10*$D$4 -> 473059.2 | E10: 168949.71 | F10: =F34 -> 482783.41 | G10: =G34 -> 518002.44 | H10: =H34 -> 535851.81 | J10: 46235 | L10: =F10+G10+H10 -> 1536637.7
C11: 46539 | D11: =E11*$D$4 -> 482783.41 | E11: 172422.65 | F11: =F36 -> 518002.44 | G11: =G36 -> 535851.81 | H11: =H36 -> 558682.55 | J11: 46266 | L11: =F11+G11+H11 -> 1612536.8
C12: 46569 | D12: =E12*$D$4 -> 518002.44 | E12: 185000.87 | F12: =F38 -> 535851.81 | G12: =G38 -> 558682.55 | H12: =H38 -> 589990.02 | J12: 46296 | L12: =F12+G12+H12 -> 1684524.4
C13: 46600 | D13: =E13*$D$4 -> 535851.81 | E13: 191375.64 | F13: =F40 -> 558682.55 | G13: =G40 -> 589990.02 | H13: =H40 -> 450405.68 | J13: 46327 | L13: =F13+G13+H13 -> 1599078.3
C14: 46631 | D14: =E14*$D$4 -> 558682.55 | E14: 199529.48 | F14: =F42 -> 589990.02 | G14: =G42 -> 450405.68 | H14: =H42 -> 222110.94 | J14: 46357 | L14: =F14+G14+H14 -> 1262506.6
C15: 46661 | D15: =E15*$D$4 -> 589990.02 | E15: 210710.72 | F15: =F44 -> 450405.68 | G15: =G44 -> 222110.94 | H15: =H44 -> 383050.41 | J15: 46388 | L15: =F15+G15+H15 -> 1055567
C16: 46692 | D16: =E16*$D$4 -> 450405.68 | E16: 160859.17 | F16: =F46 -> 222110.94 | G16: =G46 -> 383050.41 | H16: =H46 -> 428559.37 | J16: 46419 | L16: =F16+G16+H16 -> 1033720.7
C17: 46722 | D17: =E17*$D$4 -> 222110.94 | E17: 79325.334 | F17: =F48 -> 383050.41 | G17: =G48 -> 428559.37 | H17: =H48 -> 428686.43 | J17: 46447 | L17: =F17+G17+H17 -> 1240296.2
D19: =SUM(D6:D18) -> 5541256.9 | E19: =SUM(E6:E18) -> 1979020.3 | F19: =SUM(F6:F17) -> 5541256.9 | G19: =SUM(G6:G17) -> 5541256.9 | H19: =SUM(H6:H17) -> 5541256.9
C20: 12 MESES | D20: =D19/12 -> 461771.41 | E20: =E19/12 -> 164918.36
D22: Ciclo abastecimento
E23: CICLO 90 DIAS(30 PARA PRODUZIR E 60 VIAGEM E DESEMBARAÇO)
E24: ESTOQUE | F24: CHEGANDO | G24: EM TRANSITO | H24: EM PRODUÇÃO | J24: MÊS | L24: CHEGANDO | M24: EM TRANSITO | N24: EM PRODUÇÃO
D25: FAT.METRAGEM | E25: 3 | F25: 1 | G25: 1 | H25: 1 | J25: EXECUÇÃO | L25: 1 | M25: 1 | N25: 1
C26: 46388 | D26: =D6 -> 383050.41 | E26: =D26*$E$25 -> 1149151.2 | F26: =D28 -> 428559.37 | G26: =D30 -> 428686.43 | H26: =D32 -> 470074.61 | J26: JANEIRO | L26: =J28 -> FEVEREIRO | M26: =J30 -> MARÇO | N26: =J32 -> ABRIL
C28: 46419 | D28: =D7 -> 428559.37 | E28: =D28*$E$25 -> 1285678.1 | F28: =D30 -> 428686.43 | G28: =D32 -> 470074.61 | H28: =D34 -> 473059.2 | J28: FEVEREIRO | L28: =J30 -> MARÇO | M28: =J32 -> ABRIL | N28: =J34 -> MAIO
C30: 46447 | D30: =D8 -> 428686.43 | E30: =D30*$E$25 -> 1286059.3 | F30: =D32 -> 470074.61 | G30: =D34 -> 473059.2 | H30: =D36 -> 482783.41 | J30: MARÇO | L30: =J32 -> ABRIL | M30: =J34 -> MAIO | N30: =J36 -> JUNHO
C32: 46478 | D32: =D9 -> 470074.61 | E32: =D32*$E$25 -> 1410223.8 | F32: =D34 -> 473059.2 | G32: =D36 -> 482783.41 | H32: =D38 -> 518002.44 | J32: ABRIL | L32: =J34 -> MAIO | M32: =J36 -> JUNHO | N32: =J38 -> JULHO
C34: 46508 | D34: =D10 -> 473059.2 | E34: =D34*$E$25 -> 1419177.6 | F34: =D36 -> 482783.41 | G34: =D38 -> 518002.44 | H34: =D40 -> 535851.81 | J34: MAIO | L34: =J36 -> JUNHO | M34: =J38 -> JULHO | N34: =J40 -> AGOSTO
C36: 46539 | D36: =D11 -> 482783.41 | E36: =D36*$E$25 -> 1448350.2 | F36: =D38 -> 518002.44 | G36: =D40 -> 535851.81 | H36: =D42 -> 558682.55 | J36: JUNHO | L36: =J38 -> JULHO | M36: =J40 -> AGOSTO | N36: =J42 -> SETEMBRO
C38: 46569 | D38: =D12 -> 518002.44 | E38: =D38*$E$25 -> 1554007.3 | F38: =D40 -> 535851.81 | G38: =D42 -> 558682.55 | H38: =D44 -> 589990.02 | J38: JULHO | L38: =J40 -> AGOSTO | M38: =J42 -> SETEMBRO | N38: =J44 -> OUTUBRO
C40: 46600 | D40: =D13 -> 535851.81 | E40: =D40*$E$25 -> 1607555.4 | F40: =D42 -> 558682.55 | G40: =D44 -> 589990.02 | H40: =D46 -> 450405.68 | J40: AGOSTO | L40: =J42 -> SETEMBRO | M40: =J44 -> OUTUBRO | N40: =J46 -> NOVEMBRO
C42: 46631 | D42: =D14 -> 558682.55 | E42: =D42*$E$25 -> 1676047.7 | F42: =D44 -> 589990.02 | G42: =D46 -> 450405.68 | H42: =D48 -> 222110.94 | J42: SETEMBRO | L42: =J44 -> OUTUBRO | M42: =J46 -> NOVEMBRO | N42: =J48 -> DEZEMBRO
C44: 46661 | D44: =D15 -> 589990.02 | E44: =D44*$E$25 -> 1769970.1 | F44: =D46 -> 450405.68 | G44: =D48 -> 222110.94 | H44: =D26 -> 383050.41 | J44: OUTUBRO | L44: =J46 -> NOVEMBRO | M44: =J48 -> DEZEMBRO | N44: =J26 -> JANEIRO | O44: 46388
C46: 46692 | D46: =D16 -> 450405.68 | E46: =D46*$E$25 -> 1351217.1 | F46: =D48 -> 222110.94 | G46: =D26 -> 383050.41 | H46: =D28 -> 428559.37 | J46: NOVEMBRO | L46: =J48 -> DEZEMBRO | M46: =J26 -> JANEIRO | N46: =J28 -> FEVEREIRO | O46: 46419
C48: 46722 | D48: =D17 -> 222110.94 | E48: =D48*$E$25 -> 666332.81 | F48: =D26 -> 383050.41 | G48: =D28 -> 428559.37 | H48: =D30 -> 428686.43 | J48: DEZEMBRO | L48: =J26 -> JANEIRO | M48: =J28 -> FEVEREIRO | N48: =J30 -> MARÇO | O48: 46447

Sheet ANALISE
C3: Beira Rio
C4: ='CONSOLIDADO-RESUMIDO'!D6 -> 32556564 | E4: 12 | I4: COPMPOSIÇÃO-PRODUÇÃO
C5: ='CONSOLIDADO-RESUMIDO'!D7 -> 40 | E5: 0.14 | G5: 0.81 | I5: 0.8 | J5: 0.2
C6: VALOR | D6: QUANT. | E6: STK | G6: VENDA | I6: NACIONAL | J6: IMPORTADO
B7: 46388 | C7: ='CONSOLIDADO-RESUMIDO'!D9 -> 2289642.9 | D7: ='CONSOLIDADO-RESUMIDO'!E9 -> 57241.073 | E7: =C7*$E$5 -> 320550.01 | F7: =E7/$C$5 -> 8013.7502 | G7: =C7*$G$5 -> 1854610.8 | H7: =G7/$C$5 -> 46365.269 | I7: =H7+F7-J7 -> 52776.269 | J7: =F7*$J$5 -> 1602.75
B8: 46419 | C8: ='CONSOLIDADO-RESUMIDO'!D10 -> 2805147.3 | D8: ='CONSOLIDADO-RESUMIDO'!E10 -> 70128.682 | E8: =C8*$E$5 -> 392720.62 | F8: =E8/$C$5 -> 9818.0155 | G8: =C8*$G$5 -> 2272169.3 | H8: =G8/$C$5 -> 56804.233 | I8: =H8+F8-J8 -> 64658.645 | J8: =F8*$J$5 -> 1963.6031
B9: 46447 | C9: ='CONSOLIDADO-RESUMIDO'!D11 -> 2613478.9 | D9: ='CONSOLIDADO-RESUMIDO'!E11 -> 65336.973 | E9: =C9*$E$5 -> 365887.05 | F9: =E9/$C$5 -> 9147.1762 | G9: =C9*$G$5 -> 2116917.9 | H9: =G9/$C$5 -> 52922.948 | I9: =H9+F9-J9 -> 60240.689 | J9: =F9*$J$5 -> 1829.4352
B10: 46478 | C10: ='CONSOLIDADO-RESUMIDO'!D12 -> 2489204.5 | D10: ='CONSOLIDADO-RESUMIDO'!E12 -> 62230.111 | E10: =C10*$E$5 -> 348488.62 | F10: =E10/$C$5 -> 8712.2156 | G10: =C10*$G$5 -> 2016255.6 | H10: =G10/$C$5 -> 50406.39 | I10: =H10+F10-J10 -> 57376.163 | J10: =F10*$J$5 -> 1742.4431
B11: 46508 | C11: ='CONSOLIDADO-RESUMIDO'!D13 -> 2277514.5 | D11: ='CONSOLIDADO-RESUMIDO'!E13 -> 56937.864 | E11: =C11*$E$5 -> 318852.04 | F11: =E11/$C$5 -> 7971.3009 | G11: =C11*$G$5 -> 1844786.8 | H11: =G11/$C$5 -> 46119.67 | I11: =H11+F11-J11 -> 52496.71 | J11: =F11*$J$5 -> 1594.2602
B12: 46539 | C12: ='CONSOLIDADO-RESUMIDO'!D14 -> 2391390.3 | D12: ='CONSOLIDADO-RESUMIDO'!E14 -> 59784.757 | E12: =C12*$E$5 -> 334794.64 | F12: =E12/$C$5 -> 8369.866 | G12: =C12*$G$5 -> 1937026.1 | H12: =G12/$C$5 -> 48425.653 | I12: =H12+F12-J12 -> 55121.546 | J12: =F12*$J$5 -> 1673.9732
B13: 46569 | C13: ='CONSOLIDADO-RESUMIDO'!D15 -> 2934819 | D13: ='CONSOLIDADO-RESUMIDO'!E15 -> 73370.474 | E13: =C13*$E$5 -> 410874.66 | F13: =E13/$C$5 -> 10271.866 | G13: =C13*$G$5 -> 2377203.4 | H13: =G13/$C$5 -> 59430.084 | I13: =H13+F13-J13 -> 67647.577 | J13: =F13*$J$5 -> 2054.3733
B14: 46600 | C14: ='CONSOLIDADO-RESUMIDO'!D16 -> 3003174.6 | D14: ='CONSOLIDADO-RESUMIDO'!E16 -> 75079.365 | E14: =C14*$E$5 -> 420444.44 | F14: =E14/$C$5 -> 10511.111 | G14: =C14*$G$5 -> 2432571.4 | H14: =G14/$C$5 -> 60814.285 | I14: =H14+F14-J14 -> 69223.174 | J14: =F14*$J$5 -> 2102.2222
B15: 46631 | C15: ='CONSOLIDADO-RESUMIDO'!D17 -> 3687065.8 | D15: ='CONSOLIDADO-RESUMIDO'!E17 -> 92176.646 | E15: =C15*$E$5 -> 516189.22 | F15: =E15/$C$5 -> 12904.73 | G15: =C15*$G$5 -> 2986523.3 | H15: =G15/$C$5 -> 74663.083 | I15: =H15+F15-J15 -> 84986.867 | J15: =F15*$J$5 -> 2580.9461
B16: 46661 | C16: ='CONSOLIDADO-RESUMIDO'!D18 -> 3895206.6 | D16: ='CONSOLIDADO-RESUMIDO'!E18 -> 97380.166 | E16: =C16*$E$5 -> 545328.93 | F16: =E16/$C$5 -> 13633.223 | G16: =C16*$G$5 -> 3155117.4 | H16: =G16/$C$5 -> 78877.934 | I16: =H16+F16-J16 -> 89784.513 | J16: =F16*$J$5 -> 2726.6446
B17: 46692 | C17: ='CONSOLIDADO-RESUMIDO'!D19 -> 2973440.2 | D17: ='CONSOLIDADO-RESUMIDO'!E19 -> 74336.005 | E17: =C17*$E$5 -> 416281.63 | F17: =E17/$C$5 -> 10407.041 | G17: =C17*$G$5 -> 2408486.5 | H17: =G17/$C$5 -> 60212.164 | I17: =H17+F17-J17 -> 68537.796 | J17: =F17*$J$5 -> 2081.4081
B18: 46722 | C18: ='CONSOLIDADO-RESUMIDO'!D20 -> 1196479.4 | D18: ='CONSOLIDADO-RESUMIDO'!E20 -> 29911.984 | E18: =C18*$E$5 -> 167507.11 | F18: =E18/$C$5 -> 4187.6777 | G18: =C18*$G$5 -> 969148.27 | H18: =G18/$C$5 -> 24228.707 | I18: =H18+F18-J18 -> 27578.849 | J18: =F18*$J$5 -> 837.53555
C20: =SUM(C7:C19) -> 32556564 | D20: =SUM(D7:D19) -> 813914.1 | E20: =SUM(E7:E19) -> 4557919 | F20: =SUM(F7:F19) -> 113947.97 | G20: =SUM(G7:G19) -> 26370817 | H20: =SUM(H7:H19) -> 659270.42 | I20: =SUM(I7:I19) -> 750428.8 | J20: =SUM(J7:J19) -> 22789.595
B21: 12 MESES | C21: =C20/12 -> 2713047 | D21: =D20/12 -> 67826.175 | J21: =I20+J20 -> 773218.39
C25: VENDA GERAL-BRASIL
C26: ='CONSOLIDADO-RESUMIDO'!D26 -> 32443436 | E26: 12 | I26: COPMPOSIÇÃO-PRODUÇÃO
C27: ='CONSOLIDADO-RESUMIDO'!D27 -> 23 | E27: 0.8 | G27: 0.15 | I27: 0.8 | J27: 0.2
C28: VALOR | D28: QUANT. | E28: STK | G28: VENDA | I28: NACIONAL | J28: IMPORTADO
B29: 46388 | C29: ='CONSOLIDADO-RESUMIDO'!D29 -> 2219131 | D29: =C29/$C$27 -> 96483.958 | E29: =C29*$E$27 -> 1775304.8 | F29: =E29/$C$27 -> 77187.166 | G29: =C29*$G$27 -> 332869.65 | H29: =G29/$C$27 -> 14472.594 | I29: =H29+F29-J29 -> 76222.327 | J29: =F29*$J$27 -> 15437.433
B30: 46419 | C30: ='CONSOLIDADO-RESUMIDO'!D30 -> 2335927.4 | D30: =C30/$C$27 -> 101562.06 | E30: =C30*$E$27 -> 1868741.9 | F30: =E30/$C$27 -> 81249.649 | G30: =C30*$G$27 -> 350389.11 | H30: =G30/$C$27 -> 15234.309 | I30: =H30+F30-J30 -> 80234.028 | J30: =F30*$J$27 -> 16249.93
B31: 46447 | C31: ='CONSOLIDADO-RESUMIDO'!D31 -> 2452723.8 | D31: =C31/$C$27 -> 106640.16 | E31: =C31*$E$27 -> 1962179 | F31: =E31/$C$27 -> 85312.131 | G31: =C31*$G$27 -> 367908.56 | H31: =G31/$C$27 -> 15996.025 | I31: =H31+F31-J31 -> 84245.729 | J31: =F31*$J$27 -> 17062.426
B32: 46478 | C32: ='CONSOLIDADO-RESUMIDO'!D32 -> 2916664.9 | D32: =C32/$C$27 -> 126811.52 | E32: =C32*$E$27 -> 2333331.9 | F32: =E32/$C$27 -> 101449.21 | G32: =C32*$G$27 -> 437499.74 | H32: =G32/$C$27 -> 19021.728 | I32: =H32+F32-J32 -> 100181.1 | J32: =F32*$J$27 -> 20289.843
B33: 46508 | C33: ='CONSOLIDADO-RESUMIDO'!D33 -> 3072393.4 | D33: =C33/$C$27 -> 133582.32 | E33: =C33*$E$27 -> 2457914.7 | F33: =E33/$C$27 -> 106865.86 | G33: =C33*$G$27 -> 460859.01 | H33: =G33/$C$27 -> 20037.348 | I33: =H33+F33-J33 -> 105530.03 | J33: =F33*$J$27 -> 21373.171
B34: 46539 | C34: ='CONSOLIDADO-RESUMIDO'!D34 -> 3095103.8 | D34: =C34/$C$27 -> 134569.73 | E34: =C34*$E$27 -> 2476083 | F34: =E34/$C$27 -> 107655.78 | G34: =C34*$G$27 -> 464265.57 | H34: =G34/$C$27 -> 20185.46 | I34: =H34+F34-J34 -> 106310.09 | J34: =F34*$J$27 -> 21531.157
B35: 46569 | C35: ='CONSOLIDADO-RESUMIDO'!D35 -> 3098348.1 | D35: =C35/$C$27 -> 134710.79 | E35: =C35*$E$27 -> 2478678.5 | F35: =E35/$C$27 -> 107768.63 | G35: =C35*$G$27 -> 464752.22 | H35: =G35/$C$27 -> 20206.618 | I35: =H35+F35-J35 -> 106421.52 | J35: =F35*$J$27 -> 21553.726
B36: 46600 | C36: ='CONSOLIDADO-RESUMIDO'!D36 -> 3224877.5 | D36: =C36/$C$27 -> 140212.07 | E36: =C36*$E$27 -> 2579902 | F36: =E36/$C$27 -> 112169.65 | G36: =C36*$G$27 -> 483731.63 | H36: =G36/$C$27 -> 21031.81 | I36: =H36+F36-J36 -> 110767.53 | J36: =F36*$J$27 -> 22433.931
B37: 46631 | C37: ='CONSOLIDADO-RESUMIDO'!D37 -> 3026972.6 | D37: =C37/$C$27 -> 131607.5 | E37: =C37*$E$27 -> 2421578.1 | F37: =E37/$C$27 -> 105286 | G37: =C37*$G$27 -> 454045.89 | H37: =G37/$C$27 -> 19741.126 | I37: =H37+F37-J37 -> 103969.93 | J37: =F37*$J$27 -> 21057.201
B38: 46661 | C38: ='CONSOLIDADO-RESUMIDO'!D38 -> 3195678.5 | D38: =C38/$C$27 -> 138942.54 | E38: =C38*$E$27 -> 2556542.8 | F38: =E38/$C$27 -> 111154.03 | G38: =C38*$G$27 -> 479351.77 | H38: =G38/$C$27 -> 20841.381 | I38: =H38+F38-J38 -> 109764.61 | J38: =F38*$J$27 -> 22230.807
B39: 46692 | C39: ='CONSOLIDADO-RESUMIDO'!D39 -> 2439746.4 | D39: =C39/$C$27 -> 106075.93 | E39: =C39*$E$27 -> 1951797.1 | F39: =E39/$C$27 -> 84860.744 | G39: =C39*$G$27 -> 365961.96 | H39: =G39/$C$27 -> 15911.39 | I39: =H39+F39-J39 -> 83799.985 | J39: =F39*$J$27 -> 16972.149
B40: 46722 | C40: ='CONSOLIDADO-RESUMIDO'!D40 -> 1365868.7 | D40: =C40/$C$27 -> 59385.594 | E40: =C40*$E$27 -> 1092694.9 | F40: =E40/$C$27 -> 47508.475 | G40: =C40*$G$27 -> 204880.3 | H40: =G40/$C$27 -> 8907.8391 | I40: =H40+F40-J40 -> 46914.619 | J40: =F40*$J$27 -> 9501.695
C42: =SUM(C29:C41) -> 32443436 | D42: =SUM(D29:D41) -> 1410584.2 | E42: =SUM(E29:E41) -> 25954749 | F42: =SUM(F29:F41) -> 1128467.3 | G42: =SUM(G29:G41) -> 4866515.4 | H42: =SUM(H29:H41) -> 211587.63 | I42: =SUM(I29:I41) -> 1114361.5 | J42: =SUM(J29:J41) -> 225693.47
B43: 12 MESES | C43: =C42/12 -> 2703619.7 | D43: =D42/12 -> 117548.68 | J43: =I42+J42 -> 1340055
C46: VENDA GERAL CONSOLIDADA
C47: =C63 -> 65000000 | I47: COPMPOSIÇÃO-PRODUÇÃO
C48: =C63/D63 -> 29.220072 | I48: 0.8 | J48: 0.2
C49: VALOR | D49: QUANT. | E49: STK | G49: VENDA | I49: NACIONAL | J49: IMPORTADO
...
